<?xml version="1.0"?>
<robot xmlns:xacro="http://www.ros.org/wiki/xacro">
  <!-- 定义轮子宏：通过side区分左右，sign控制位置符号 -->
  <xacro:macro name="wheel" params="side sign">
    <link name="wheel_${side}_link">
      <visual>
        <origin xyz="0 0 0" rpy="1.5708 0 0"/>
        <geometry>
          <cylinder radius="${wheel_radius}" length="${wheel_length}"/>
        </geometry>
        <material name="black">
          <color rgba="0 0 0 1"/>
        </material>
      </visual>
      <collision>
        <origin xyz="0 0 0" rpy="1.5708 0 0"/>
        <geometry>
          <cylinder radius="${wheel_radius}" length="${wheel_length}"/>
        </geometry>
      </collision>
      <inertial>
        <mass value="${wheel_mass}"/>
        <inertia ixx="0.01" ixy="0" ixz="0" iyy="0.01" iyz="0" izz="0.01"/>
      </inertial>
    </link>

    <joint name="wheel_${side}_joint" type="continuous">
      <parent link="base_link"/>
      <child link="wheel_${side}_link"/>
      <origin xyz="${wheel_x_offset}${sign * wheel_separation/2} -0.05" rpy="0 0 0"/>
      <axis xyz="0 1 0"/>
      <limit effort="100" velocity="10"/>
    </joint>
  </xacro:macro>

  <!-- 调用宏生成左轮和右轮 -->
  <xacro:wheel side="left" sign="1"/>
  <xacro:wheel side="right" sign="-1"/>
</robot>
